Workbook

Sheet Tier 1 - Priority Targets
A1: Company | B1: Website | C1: Careers Page | D1: Industry / Sector | E1: Industry Emphasized | F1: NAICS Code(s) | G1: NAICS Code Type | H1: Why This NAICS Code | I1: HQ Location / Footprint | J1: Company Size | K1: Revenue Band / Latest Revenue | L1: Growth / Revenue Signal | M1: Hiring Signal | N1: Recent Hiring Trends | O1: Salary Range (if posted) | P1: Opportunity Relevance | Q1: Opportunity Fit | R1: Category | S1: Why This Fits | T1: Executive Role Fit | U1: Warm Introduction Path | V1: Outreach Approach | W1: Key Contacts / Priority Titles | X1: Compensation Benchmark | Y1: Suggested Search Keywords | Z1: Suggested Job Title Keywords | AA1: Source URL | AB1: Priority Score | AC1: Suggested Priority Rank (1-25) | AD1: Status | AE1: Next Action | AF1: Date Researched | AG1: _GrowthPts | AH1: _HiringPts | AI1: _RecentHiringPts | AJ1: _OppRelPts | AK1: _OppFitPts | AL1: _TieBreakRank
A2: Deloitte | B2: https://www2.deloitte.com | C2: https://apply.deloitte.com/careers | D2: Management & Technology Consulting | E2: Cyber risk advisory for critical infrastructure and industrial clients | F2: 541611, 541512, 541990 | G2: Primary | H2: Keyword used: "Consulting, Advisory" -> 541611 (Management Consulting) as primary; "Information Technology" -> 541512 (Computer Systems Design) and 541990 (misc professional/scientific/technical) as secondary, reflecting Deloitte's IT and broader advisory lines. | I2: New York, NY, USA — global | J2: 400,000+ employees globally | K2: ~$67B (FY2025, global network revenue, publicly reported) | L2: High — global consulting demand for OT/ICS risk continues to grow with critical infrastructure regulation (NERC CIP, EU NIS2) | M2: Medium — steady but not aggressive hiring signal in OT-specific cyber risk roles based on overall firm trajectory | N2: Not independently verified this pass | P2: High — global scale, established OT/ICS cyber risk practice, frequent Director/Partner-track hiring | Q2: High | R2: Global Big 4 / Major Consulting | S2: Direct-fit Big 4 firm with an active cyber risk practice serving industrial/critical infrastructure clients; matches Tom's practice-building background at EY/Accenture. | T2: Managing Director / Principal, Cyber Risk (OT/ICS) | U2: LinkedIn 2nd-degree via former EY/Accenture colleagues who moved to Deloitte; industry conference contacts (S4, SANS ICS Summit) | V2: Approach via a Deloitte Cyber Risk Managing Director referral or executive search firm specializing in Big 4 lateral partner hires | W2: Practice-level: Managing Director, Cyber Risk – OT/ICS (title-level, no named individual publicly confirmed this pass) | X2: Not applicable — Deloitte is a private partnership and does not file a 10-K/proxy | Y2: OT cybersecurity Deloitte, Deloitte cyber risk industrial, Deloitte ICS practice | Z2: Managing Director Cyber Risk OT, Principal OT/ICS Security, Cyber Risk Industrials Leader | AA2: https://www2.deloitte.com; general knowledge, not independently re-verified via search this pass | AC2: =ROUND((AK2*2)+(AJ2*2)+AVERAGE(AG2,AH2,AI2),1) -> 18.3 | AF2: August 11, 2026 | AG2: =IF(ISNUMBER(SEARCH("Very High",L2)),5,IF(ISNUMBER(SEARCH("Medium-High",L2)),3.5,IF(ISNUMBER(SEARCH("Low-Medium",L2)),2,IF(ISNUMBER(SEARCH("High",L2)),4,IF(ISNUMBER(SEARCH("Medium",L2)),3,IF(ISNUMBER(SEARCH("Low",L2)),1,0)))))) -> 4 | AH2: =IF(ISNUMBER(SEARCH("Very High",M2)),5,IF(ISNUMBER(SEARCH("Medium-High",M2)),3.5,IF(ISNUMBER(SEARCH("Low-Medium",M2)),2,IF(ISNUMBER(SEARCH("High",M2)),4,IF(ISNUMBER(SEARCH("Medium",M2)),3,IF(ISNUMBER(SEARCH("Low",M2)),1,0)))))) -> 3 | AI2: =IF(ISNUMBER(SEARCH("Very High",N2)),5,IF(ISNUMBER(SEARCH("Medium-High",N2)),3.5,IF(ISNUMBER(SEARCH("Low-Medium",N2)),2,IF(ISNUMBER(SEARCH("High",N2)),4,IF(ISNUMBER(SEARCH("Medium",N2)),3,IF(ISNUMBER(SEARCH("Low",N2)),1,0)))))) -> 0 | AJ2: =IF(ISNUMBER(SEARCH("Very High",P2)),5,IF(ISNUMBER(SEARCH("Medium-High",P2)),3.5,IF(ISNUMBER(SEARCH("Low-Medium",P2)),2,IF(ISNUMBER(SEARCH("High",P2)),4,IF(ISNUMBER(SEARCH("Medium",P2)),3,IF(ISNUMBER(SEARCH("Low",P2)),1,0)))))) -> 4 | AK2: =IF(ISNUMBER(SEARCH("Very High",Q2)),5,IF(ISNUMBER(SEARCH("Medium-High",Q2)),3.5,IF(ISNUMBER(SEARCH("Low-Medium",Q2)),2,IF(ISNUMBER(SEARCH("High",Q2)),4,IF(ISNUMBER(SEARCH("Medium",Q2)),3,IF(ISNUMBER(SEARCH("Low",Q2)),1,0)))))) -> 4 | AL2: =AC2+ROW()/10000000 -> 18.3
A3: EY | B3: https://www.ey.com | C3: https://careers.ey.com | D3: Professional Services / Consulting | E3: OT cybersecurity consulting for critical infrastructure, energy, and manufacturing | F3: 541611, 541512, 541990 | G3: Primary | H3: Keyword used: "Consulting, Advisory" -> 541611 primary; "Information Technology" -> 541512 and 541990 secondary, reflecting EY's technology consulting and broader advisory lines. | I3: London, UK — global (US headquartered operations in multiple cities) | J3: 400,000+ employees globally | K3: ~$51.2B (FY2025, global network revenue, publicly reported) | L3: High — EY continues investing in cyber risk as part of its broader consulting growth strategy | M3: Medium | N3: Not independently verified this pass | P3: Very High — direct former employer, practice Tom personally founded and scaled to $10M–30M+ | Q3: High | R3: Former Employer / Direct Alumni Network | S3: Tom personally founded and scaled EY's global OT cybersecurity practice from zero; strongest warm-network fit on this list. | T3: Partner / Principal, OT Cybersecurity Consulting | U3: Direct — former colleagues and practice team Tom built from 2016-2020; strongest warm-intro path on the entire list | V3: Direct outreach to former EY OT cyber colleagues/leadership; leverage practice he built as a credibility anchor | W3: Direct alumni network (not independently re-verified this pass — Tom's own contacts are the strongest source here) | X3: Not applicable — EY is a private partnership and does not file a 10-K/proxy | Y3: EY OT cybersecurity, EY cyber risk industrial, Ernst Young ICS practice | Z3: Partner OT Cybersecurity, Principal Cyber Risk Industrials, OT Security Practice Leader | AA3: https://www.ey.com; Tom's resume (former employer) | AC3: =ROUND((AK3*2)+(AJ3*2)+AVERAGE(AG3,AH3,AI3),1) -> 20.3 | AF3: August 11, 2026 | AG3: =IF(ISNUMBER(SEARCH("Very High",L3)),5,IF(ISNUMBER(SEARCH("Medium-High",L3)),3.5,IF(ISNUMBER(SEARCH("Low-Medium",L3)),2,IF(ISNUMBER(SEARCH("High",L3)),4,IF(ISNUMBER(SEARCH("Medium",L3)),3,IF(ISNUMBER(SEARCH("Low",L3)),1,0)))))) -> 4 | AH3: =IF(ISNUMBER(SEARCH("Very High",M3)),5,IF(ISNUMBER(SEARCH("Medium-High",M3)),3.5,IF(ISNUMBER(SEARCH("Low-Medium",M3)),2,IF(ISNUMBER(SEARCH("High",M3)),4,IF(ISNUMBER(SEARCH("Medium",M3)),3,IF(ISNUMBER(SEARCH("Low",M3)),1,0)))))) -> 3 | AI3: =IF(ISNUMBER(SEARCH("Very High",N3)),5,IF(ISNUMBER(SEARCH("Medium-High",N3)),3.5,IF(ISNUMBER(SEARCH("Low-Medium",N3)),2,IF(ISNUMBER(SEARCH("High",N3)),4,IF(ISNUMBER(SEARCH("Medium",N3)),3,IF(ISNUMBER(SEARCH("Low",N3)),1,0)))))) -> 0 | AJ3: =IF(ISNUMBER(SEARCH("Very High",P3)),5,IF(ISNUMBER(SEARCH("Medium-High",P3)),3.5,IF(ISNUMBER(SEARCH("Low-Medium",P3)),2,IF(ISNUMBER(SEARCH("High",P3)),4,IF(ISNUMBER(SEARCH("Medium",P3)),3,IF(ISNUMBER(SEARCH("Low",P3)),1,0)))))) -> 5 | AK3: =IF(ISNUMBER(SEARCH("Very High",Q3)),5,IF(ISNUMBER(SEARCH("Medium-High",Q3)),3.5,IF(ISNUMBER(SEARCH("Low-Medium",Q3)),2,IF(ISNUMBER(SEARCH("High",Q3)),4,IF(ISNUMBER(SEARCH("Medium",Q3)),3,IF(ISNUMBER(SEARCH("Low",Q3)),1,0)))))) -> 4 | AL3: =AC3+ROW()/10000000 -> 20.3
A4: KPMG | B4: https://kpmg.com | C4: https://kpmg.com/us/en/careers.html | D4: Professional Services / Consulting | E4: Regulatory readiness and third-party risk consulting for industrial/critical infrastructure clients | F4: 541611, 541512, 541990 | G4: Primary | H4: Keyword used: "Consulting, Advisory" -> 541611 primary; "Information Technology" -> 541512 and 541990 secondary, reflecting KPMG's technology and broader advisory practices. | I4: Amstelveen, Netherlands — global | J4: 275,000+ employees globally | K4: ~$38B (FY2025, global network revenue, publicly reported) | L4: Medium-High | M4: Medium | N4: Not independently verified this pass | P4: Medium-High — Big 4 scale with a maturity-assessment-focused OT practice, but less specialized than EY/Accenture in this niche | Q4: Medium-High | R4: Global Big 4 / Major Consulting | S4: Big 4 firm with a recognized OT/ICS regulatory readiness and maturity-assessment practice; solid Director/Partner-track target. | T4: Managing Director / Principal, Cyber Security (OT/ICS) | U4: LinkedIn 2nd-degree via Big 4 alumni network; industry conference contacts | V4: Approach via executive search firm specializing in Big 4 lateral partner hires | W4: Practice-level title only — no named individual independently confirmed this pass | X4: Not applicable — KPMG is a private partnership and does not file a 10-K/proxy | Y4: KPMG OT cybersecurity, KPMG cyber risk industrial | Z4: Managing Director Cyber Security OT, Principal ICS Risk Advisory | AA4: https://kpmg.com; general knowledge | AC4: =ROUND((AK4*2)+(AJ4*2)+AVERAGE(AG4,AH4,AI4),1) -> 16.2 | AF4: August 11, 2026 | AG4: =IF(ISNUMBER(SEARCH("Very High",L4)),5,IF(ISNUMBER(SEARCH("Medium-High",L4)),3.5,IF(ISNUMBER(SEARCH("Low-Medium",L4)),2,IF(ISNUMBER(SEARCH("High",L4)),4,IF(ISNUMBER(SEARCH("Medium",L4)),3,IF(ISNUMBER(SEARCH("Low",L4)),1,0)))))) -> 3.5 | AH4: =IF(ISNUMBER(SEARCH("Very High",M4)),5,IF(ISNUMBER(SEARCH("Medium-High",M4)),3.5,IF(ISNUMBER(SEARCH("Low-Medium",M4)),2,IF(ISNUMBER(SEARCH("High",M4)),4,IF(ISNUMBER(SEARCH("Medium",M4)),3,IF(ISNUMBER(SEARCH("Low",M4)),1,0)))))) -> 3 | AI4: =IF(ISNUMBER(SEARCH("Very High",N4)),5,IF(ISNUMBER(SEARCH("Medium-High",N4)),3.5,IF(ISNUMBER(SEARCH("Low-Medium",N4)),2,IF(ISNUMBER(SEARCH("High",N4)),4,IF(ISNUMBER(SEARCH("Medium",N4)),3,IF(ISNUMBER(SEARCH("Low",N4)),1,0)))))) -> 0 | AJ4: =IF(ISNUMBER(SEARCH("Very High",P4)),5,IF(ISNUMBER(SEARCH("Medium-High",P4)),3.5,IF(ISNUMBER(SEARCH("Low-Medium",P4)),2,IF(ISNUMBER(SEARCH("High",P4)),4,IF(ISNUMBER(SEARCH("Medium",P4)),3,IF(ISNUMBER(SEARCH("Low",P4)),1,0)))))) -> 3.5 | AK4: =IF(ISNUMBER(SEARCH("Very High",Q4)),5,IF(ISNUMBER(SEARCH("Medium-High",Q4)),3.5,IF(ISNUMBER(SEARCH("Low-Medium",Q4)),2,IF(ISNUMBER(SEARCH("High",Q4)),4,IF(ISNUMBER(SEARCH("Medium",Q4)),3,IF(ISNUMBER(SEARCH("Low",Q4)),1,0)))))) -> 3.5 | AL4: =AC4+ROW()/10000000 -> 16.2
A5: PwC | B5: https://www.pwc.com | C5: https://www.pwc.com/us/en/careers.html | D5: Professional Services / Consulting | E5: Risk quantification and ESG-linked cybersecurity advisory for industrial clients | F5: 541611, 541512, 541990 | G5: Primary | H5: Keyword used: "Consulting, Advisory" -> 541611 primary; "Information Technology" -> 541512 and 541990 secondary, reflecting PwC's technology consulting and Strategy& advisory lines. | I5: London, UK — global | J5: 370,000+ employees globally | K5: ~$55.4B (FY2025, global network revenue, publicly reported) | L5: Medium-High | M5: Medium | N5: Not independently verified this pass | P5: Medium-High — Big 4 scale, risk-quantification angle is a differentiated but narrower OT niche than EY/Accenture | Q5: Medium-High | R5: Global Big 4 / Major Consulting | S5: Big 4 firm with board-level risk-quantification consulting that complements Tom's board/C-suite advisory experience. | T5: Managing Director / Principal, Cyber Risk (OT/ICS) | U5: LinkedIn 2nd-degree via Big 4 alumni network | V5: Approach via executive search firm specializing in Big 4 lateral partner hires | W5: Practice-level title only — no named individual independently confirmed this pass | X5: Not applicable — PwC is a private partnership and does not file a 10-K/proxy | Y5: PwC OT cybersecurity, PwC cyber risk industrial | Z5: Managing Director Cyber Risk OT, Principal Industrial Cyber Risk | AA5: https://www.pwc.com; general knowledge | AC5: =ROUND((AK5*2)+(AJ5*2)+AVERAGE(AG5,AH5,AI5),1) -> 16.2 | AF5: August 11, 2026 | AG5: =IF(ISNUMBER(SEARCH("Very High",L5)),5,IF(ISNUMBER(SEARCH("Medium-High",L5)),3.5,IF(ISNUMBER(SEARCH("Low-Medium",L5)),2,IF(ISNUMBER(SEARCH("High",L5)),4,IF(ISNUMBER(SEARCH("Medium",L5)),3,IF(ISNUMBER(SEARCH("Low",L5)),1,0)))))) -> 3.5 | AH5: =IF(ISNUMBER(SEARCH("Very High",M5)),5,IF(ISNUMBER(SEARCH("Medium-High",M5)),3.5,IF(ISNUMBER(SEARCH("Low-Medium",M5)),2,IF(ISNUMBER(SEARCH("High",M5)),4,IF(ISNUMBER(SEARCH("Medium",M5)),3,IF(ISNUMBER(SEARCH("Low",M5)),1,0)))))) -> 3 | AI5: =IF(ISNUMBER(SEARCH("Very High",N5)),5,IF(ISNUMBER(SEARCH("Medium-High",N5)),3.5,IF(ISNUMBER(SEARCH("Low-Medium",N5)),2,IF(ISNUMBER(SEARCH("High",N5)),4,IF(ISNUMBER(SEARCH("Medium",N5)),3,IF(ISNUMBER(SEARCH("Low",N5)),1,0)))))) -> 0 | AJ5: =IF(ISNUMBER(SEARCH("Very High",P5)),5,IF(ISNUMBER(SEARCH("Medium-High",P5)),3.5,IF(ISNUMBER(SEARCH("Low-Medium",P5)),2,IF(ISNUMBER(SEARCH("High",P5)),4,IF(ISNUMBER(SEARCH("Medium",P5)),3,IF(ISNUMBER(SEARCH("Low",P5)),1,0)))))) -> 3.5 | AK5: =IF(ISNUMBER(SEARCH("Very High",Q5)),5,IF(ISNUMBER(SEARCH("Medium-High",Q5)),3.5,IF(ISNUMBER(SEARCH("Low-Medium",Q5)),2,IF(ISNUMBER(SEARCH("High",Q5)),4,IF(ISNUMBER(SEARCH("Medium",Q5)),3,IF(ISNUMBER(SEARCH("Low",Q5)),1,0)))))) -> 3.5 | AL5: =AC5+ROW()/10000000 -> 16.200001
A6: Accenture | B6: https://www.accenture.com | C6: https://www.accenture.com/us-en/careers | D6: Technology & Management Consulting | E6: OT security integrated with Industry 4.0 / smart-factory digital transformation | F6: 541512, 541611, 541990 | G6: Primary | H6: Keyword used: "Information Technology" -> 541512 primary; "Consulting, Advisory" -> 541611 and 541990 secondary, reflecting Accenture's blend of IT delivery and management consulting. | I6: Dublin, Ireland — global (major US operations) | J6: 775,000+ employees globally | K6: ~$69.7B (FY2025, publicly traded, NYSE: ACN) | L6: High — Accenture's security practice continues to grow alongside AI and cloud-OT integration demand | M6: Medium-High | N6: Not independently verified this pass | P6: Very High — direct former employer; Tom personally scaled the OT security capability here | Q6: High | R6: Former Employer / Direct Alumni Network | S6: Tom built and scaled Accenture's global OT cybersecurity capability from a limited footprint; strong warm-network fit and public-company target with 10-K/proxy visibility. | T6: Managing Director, Security (OT/ICS) | U6: Direct — former colleagues from 2021-2022 tenure | V6: Direct outreach to former Accenture Security colleagues/leadership | W6: Practice-level: Global Security Lead / Managing Director, OT Security (per FY2025 10-K, Accenture's proxy discloses executive officers but does not name a company-wide CISO as a Named Executive Officer) | X6: Not a Named Executive Officer — not disclosed in Accenture's FY2025 proxy Summary Compensation Table (security/OT leadership roles below NEO threshold) | Y6: Accenture OT security, Accenture Security industrial, Accenture ICS practice | Z6: Managing Director Security OT, Senior Manager OT Cybersecurity | AA6: https://www.accenture.com; Tom's resume (former employer); Accenture FY2025 proxy general knowledge, not independently re-verified this pass | AC6: =ROUND((AK6*2)+(AJ6*2)+AVERAGE(AG6,AH6,AI6),1) -> 20.5 | AF6: August 11, 2026 | AG6: =IF(ISNUMBER(SEARCH("Very High",L6)),5,IF(ISNUMBER(SEARCH("Medium-High",L6)),3.5,IF(ISNUMBER(SEARCH("Low-Medium",L6)),2,IF(ISNUMBER(SEARCH("High",L6)),4,IF(ISNUMBER(SEARCH("Medium",L6)),3,IF(ISNUMBER(SEARCH("Low",L6)),1,0)))))) -> 4 | AH6: =IF(ISNUMBER(SEARCH("Very High",M6)),5,IF(ISNUMBER(SEARCH("Medium-High",M6)),3.5,IF(ISNUMBER(SEARCH("Low-Medium",M6)),2,IF(ISNUMBER(SEARCH("High",M6)),4,IF(ISNUMBER(SEARCH("Medium",M6)),3,IF(ISNUMBER(SEARCH("Low",M6)),1,0)))))) -> 3.5 | AI6: =IF(ISNUMBER(SEARCH("Very High",N6)),5,IF(ISNUMBER(SEARCH("Medium-High",N6)),3.5,IF(ISNUMBER(SEARCH("Low-Medium",N6)),2,IF(ISNUMBER(SEARCH("High",N6)),4,IF(ISNUMBER(SEARCH("Medium",N6)),3,IF(ISNUMBER(SEARCH("Low",N6)),1,0)))))) -> 0 | AJ6: =IF(ISNUMBER(SEARCH("Very High",P6)),5,IF(ISNUMBER(SEARCH("Medium-High",P6)),3.5,IF(ISNUMBER(SEARCH("Low-Medium",P6)),2,IF(ISNUMBER(SEARCH("High",P6)),4,IF(ISNUMBER(SEARCH("Medium",P6)),3,IF(ISNUMBER(SEARCH("Low",P6)),1,0)))))) -> 5 | AK6: =IF(ISNUMBER(SEARCH("Very High",Q6)),5,IF(ISNUMBER(SEARCH("Medium-High",Q6)),3.5,IF(ISNUMBER(SEARCH("Low-Medium",Q6)),2,IF(ISNUMBER(SEARCH("High",Q6)),4,IF(ISNUMBER(SEARCH("Medium",Q6)),3,IF(ISNUMBER(SEARCH("Low",Q6)),1,0)))))) -> 4 | AL6: =AC6+ROW()/10000000 -> 20.500001
A7: IBM | B7: https://www.ibm.com | C7: https://www.ibm.com/careers | D7: Technology / IT Consulting | E7: OT security integrated with X-Force threat intelligence and hybrid cloud-to-OT connectivity | F7: 541512, 541990, 511210 | G7: Primary | H7: Keyword used: "Information Technology" -> 541512 primary; 541990 secondary for IBM Consulting's broader advisory; 511210 (Software Publishers) secondary for IBM's own software portfolio. | I7: Armonk, NY, USA | J7: 280,000+ employees globally | K7: ~$62.8B (FY2025, publicly traded, NYSE: IBM) | L7: Medium-High | M7: Medium | N7: Not independently verified this pass | P7: Medium-High — strong brand and X-Force threat intel angle, but OT is a smaller slice of a very large portfolio | Q7: Medium-High | R7: Global Technology / IT Consulting | S7: IBM Consulting's OT security practice, tied to X-Force threat intelligence, is a credible Director-level target given Tom's zero-trust and segmentation background. | T7: Associate Partner / Partner, Cybersecurity Services (OT) | U7: LinkedIn 2nd-degree via industry conference contacts (Dragos/Nozomi/Claroty ecosystem overlaps with IBM partnerships) | V7: Approach via IBM Consulting recruiter or executive search firm | W7: Named CISO per FY2025 10-K Item 1C disclosure: IBM discloses a Chief Information Security Officer role in its cybersecurity governance section but the individual named is enterprise-wide, not OT-specific (not independently re-verified this pass) | X7: Not a Named Executive Officer — not disclosed in IBM's most recent proxy Summary Compensation Table | Y7: IBM OT security, IBM X-Force ICS, IBM Consulting industrial cybersecurity | Z7: Partner Cybersecurity Services OT, Associate Partner Industrial Security | AA7: https://www.ibm.com; general knowledge, not independently re-verified via search this pass | AC7: =ROUND((AK7*2)+(AJ7*2)+AVERAGE(AG7,AH7,AI7),1) -> 16.2 | AF7: August 11, 2026 | AG7: =IF(ISNUMBER(SEARCH("Very High",L7)),5,IF(ISNUMBER(SEARCH("Medium-High",L7)),3.5,IF(ISNUMBER(SEARCH("Low-Medium",L7)),2,IF(ISNUMBER(SEARCH("High",L7)),4,IF(ISNUMBER(SEARCH("Medium",L7)),3,IF(ISNUMBER(SEARCH("Low",L7)),1,0)))))) -> 3.5 | AH7: =IF(ISNUMBER(SEARCH("Very High",M7)),5,IF(ISNUMBER(SEARCH("Medium-High",M7)),3.5,IF(ISNUMBER(SEARCH("Low-Medium",M7)),2,IF(ISNUMBER(SEARCH("High",M7)),4,IF(ISNUMBER(SEARCH("Medium",M7)),3,IF(ISNUMBER(SEARCH("Low",M7)),1,0)))))) -> 3 | AI7: =IF(ISNUMBER(SEARCH("Very High",N7)),5,IF(ISNUMBER(SEARCH("Medium-High",N7)),3.5,IF(ISNUMBER(SEARCH("Low-Medium",N7)),2,IF(ISNUMBER(SEARCH("High",N7)),4,IF(ISNUMBER(SEARCH("Medium",N7)),3,IF(ISNUMBER(SEARCH("Low",N7)),1,0)))))) -> 0 | AJ7: =IF(ISNUMBER(SEARCH("Very High",P7)),5,IF(ISNUMBER(SEARCH("Medium-High",P7)),3.5,IF(ISNUMBER(SEARCH("Low-Medium",P7)),2,IF(ISNUMBER(SEARCH("High",P7)),4,IF(ISNUMBER(SEARCH("Medium",P7)),3,IF(ISNUMBER(SEARCH("Low",P7)),1,0)))))) -> 3.5 | AK7: =IF(ISNUMBER(SEARCH("Very High",Q7)),5,IF(ISNUMBER(SEARCH("Medium-High",Q7)),3.5,IF(ISNUMBER(SEARCH("Low-Medium",Q7)),2,IF(ISNUMBER(SEARCH("High",Q7)),4,IF(ISNUMBER(SEARCH("Medium",Q7)),3,IF(ISNUMBER(SEARCH("Low",Q7)),1,0)))))) -> 3.5 | AL7: =AC7+ROW()/10000000 -> 16.200001
A8: Capgemini | B8: https://www.capgemini.com | C8: https://www.capgemini.com/careers/ | D8: Technology & Engineering Consulting | E8: OT/IoT security within broader Industry 4.0 engineering services | F8: 541512, 541690, 541611 | G8: Primary | H8: Keyword used: "Information Technology" -> 541512 primary; "Operational Technology" -> 541690 secondary for engineering/OT services; 541611 secondary for management consulting arm. | I8: Paris, France — global | J8: 340,000+ employees globally | K8: ~€22.1B (FY2025, publicly traded, Euronext Paris: CAP) | L8: Medium | M8: Medium | N8: Not independently verified this pass | P8: Medium — large scale but OT security is a smaller, less specialized line than at EY/Accenture | Q8: Medium | R8: Global IT/Engineering Services | S8: Large systems integrator with an OT/IoT security line; a plausible Director-level target but less specialized bench than pure-play OT firms. | T8: Vice President / Practice Lead, Cybersecurity (OT) | U8: LinkedIn 2nd-degree via industry conference contacts | V8: Approach via recruiter or LinkedIn outreach to Capgemini Cybersecurity practice leadership | W8: Practice-level title only — no named individual independently confirmed this pass | X8: Not independently verified this pass — Euronext-listed, French governance disclosure differs from US 10-K/proxy format | Y8: Capgemini OT security, Capgemini cybersecurity industrial | Z8: VP Cybersecurity OT, Practice Lead Industrial Security | AA8: https://www.capgemini.com; general knowledge | AC8: =ROUND((AK8*2)+(AJ8*2)+AVERAGE(AG8,AH8,AI8),1) -> 14 | AF8: August 11, 2026 | AG8: =IF(ISNUMBER(SEARCH("Very High",L8)),5,IF(ISNUMBER(SEARCH("Medium-High",L8)),3.5,IF(ISNUMBER(SEARCH("Low-Medium",L8)),2,IF(ISNUMBER(SEARCH("High",L8)),4,IF(ISNUMBER(SEARCH("Medium",L8)),3,IF(ISNUMBER(SEARCH("Low",L8)),1,0)))))) -> 3 | AH8: =IF(ISNUMBER(SEARCH("Very High",M8)),5,IF(ISNUMBER(SEARCH("Medium-High",M8)),3.5,IF(ISNUMBER(SEARCH("Low-Medium",M8)),2,IF(ISNUMBER(SEARCH("High",M8)),4,IF(ISNUMBER(SEARCH("Medium",M8)),3,IF(ISNUMBER(SEARCH("Low",M8)),1,0)))))) -> 3 | AI8: =IF(ISNUMBER(SEARCH("Very High",N8)),5,IF(ISNUMBER(SEARCH("Medium-High",N8)),3.5,IF(ISNUMBER(SEARCH("Low-Medium",N8)),2,IF(ISNUMBER(SEARCH("High",N8)),4,IF(ISNUMBER(SEARCH("Medium",N8)),3,IF(ISNUMBER(SEARCH("Low",N8)),1,0)))))) -> 0 | AJ8: =IF(ISNUMBER(SEARCH("Very High",P8)),5,IF(ISNUMBER(SEARCH("Medium-High",P8)),3.5,IF(ISNUMBER(SEARCH("Low-Medium",P8)),2,IF(ISNUMBER(SEARCH("High",P8)),4,IF(ISNUMBER(SEARCH("Medium",P8)),3,IF(ISNUMBER(SEARCH("Low",P8)),1,0)))))) -> 3 | AK8: =IF(ISNUMBER(SEARCH("Very High",Q8)),5,IF(ISNUMBER(SEARCH("Medium-High",Q8)),3.5,IF(ISNUMBER(SEARCH("Low-Medium",Q8)),2,IF(ISNUMBER(SEARCH("High",Q8)),4,IF(ISNUMBER(SEARCH("Medium",Q8)),3,IF(ISNUMBER(SEARCH("Low",Q8)),1,0)))))) -> 3 | AL8: =AC8+ROW()/10000000 -> 14.000001
A9: CGI | B9: https://www.cgi.com | C9: https://www.cgi.com/en/careers | D9: IT Services & Consulting | E9: OT/IT convergence security for utilities and government clients | F9: 541512, 541611 | G9: Primary | H9: Keyword used: "Information Technology" -> 541512 primary; "Consulting" -> 541611 secondary for CGI's business consulting practice. | I9: Montreal, Canada — global | J9: 94,000+ employees globally | K9: ~C$14.7B (FY2025, publicly traded, TSX/NYSE: GIB.A/GIB) | L9: Medium | M9: Low-Medium | N9: Not independently verified this pass | P9: Medium — solid utility-sector OT presence but not a headline OT security brand | Q9: Medium | R9: Global IT/Engineering Services | S9: CGI's utility and government client base overlaps with Tom's critical infrastructure focus, though its OT security practice is less prominent than Big 4 peers. | T9: Vice President, Cybersecurity Consulting (OT) | U9: LinkedIn 2nd-degree via industry conference contacts | V9: Approach via recruiter or LinkedIn outreach to CGI Cybersecurity leadership | W9: Practice-level title only — no named individual independently confirmed this pass | X9: Not independently verified this pass | Y9: CGI OT security, CGI cybersecurity utilities | Z9: VP Cybersecurity OT, Director Industrial IT Security | AA9: https://www.cgi.com; general knowledge | AC9: =ROUND((AK9*2)+(AJ9*2)+AVERAGE(AG9,AH9,AI9),1) -> 13.7 | AF9: August 11, 2026 | AG9: =IF(ISNUMBER(SEARCH("Very High",L9)),5,IF(ISNUMBER(SEARCH("Medium-High",L9)),3.5,IF(ISNUMBER(SEARCH("Low-Medium",L9)),2,IF(ISNUMBER(SEARCH("High",L9)),4,IF(ISNUMBER(SEARCH("Medium",L9)),3,IF(ISNUMBER(SEARCH("Low",L9)),1,0)))))) -> 3 | AH9: =IF(ISNUMBER(SEARCH("Very High",M9)),5,IF(ISNUMBER(SEARCH("Medium-High",M9)),3.5,IF(ISNUMBER(SEARCH("Low-Medium",M9)),2,IF(ISNUMBER(SEARCH("High",M9)),4,IF(ISNUMBER(SEARCH("Medium",M9)),3,IF(ISNUMBER(SEARCH("Low",M9)),1,0)))))) -> 2 | AI9: =IF(ISNUMBER(SEARCH("Very High",N9)),5,IF(ISNUMBER(SEARCH("Medium-High",N9)),3.5,IF(ISNUMBER(SEARCH("Low-Medium",N9)),2,IF(ISNUMBER(SEARCH("High",N9)),4,IF(ISNUMBER(SEARCH("Medium",N9)),3,IF(ISNUMBER(SEARCH("Low",N9)),1,0)))))) -> 0 | AJ9: =IF(ISNUMBER(SEARCH("Very High",P9)),5,IF(ISNUMBER(SEARCH("Medium-High",P9)),3.5,IF(ISNUMBER(SEARCH("Low-Medium",P9)),2,IF(ISNUMBER(SEARCH("High",P9)),4,IF(ISNUMBER(SEARCH("Medium",P9)),3,IF(ISNUMBER(SEARCH("Low",P9)),1,0)))))) -> 3 | AK9: =IF(ISNUMBER(SEARCH("Very High",Q9)),5,IF(ISNUMBER(SEARCH("Medium-High",Q9)),3.5,IF(ISNUMBER(SEARCH("Low-Medium",Q9)),2,IF(ISNUMBER(SEARCH("High",Q9)),4,IF(ISNUMBER(SEARCH("Medium",Q9)),3,IF(ISNUMBER(SEARCH("Low",Q9)),1,0)))))) -> 3 | AL9: =AC9+ROW()/10000000 -> 13.700001
A10: Atos / Eviden | B10: https://eviden.com | C10: https://eviden.com/careers/ | D10: IT Services & Cybersecurity | E10: Sovereign cloud and OT security for European critical infrastructure | F10: 541512, 541690 | G10: Primary | H10: Keyword used: "Information Technology" -> 541512 primary; "Operational Technology" -> 541690 secondary for Eviden's critical-infrastructure/OT security work. | I10: Bezons, France — global | J10: ~50,000 employees (Eviden, post-restructuring) | K10: ~€5B (Eviden segment, approximate, FY2025 — Atos group has undergone significant financial restructuring in recent years) | L10: Low-Medium — Atos/Eviden has faced well-publicized financial and restructuring challenges | M10: Low-Medium | N10: Not independently verified this pass | P10: Medium — genuine European OT/critical-infrastructure credentials, but corporate instability is a real risk factor for a leadership hire | Q10: Medium | R10: Global IT/Engineering Services | S10: Strong sovereign/European critical-infrastructure credentials, tempered by Atos's recent financial restructuring — worth flagging as higher-risk than peers. | T10: Vice President, Cybersecurity Products (OT) | U10: LinkedIn 2nd-degree via industry conference contacts | V10: Approach cautiously given recent corporate restructuring; verify current organizational stability before pursuing | W10: Practice-level title only — no named individual independently confirmed this pass | X10: Not independently verified this pass — Euronext-listed, French governance disclosure differs from US 10-K/proxy format | Y10: Eviden OT security, Atos cybersecurity industrial | Z10: VP Cybersecurity OT, Director Industrial Security Eviden | AA10: https://eviden.com; general knowledge — note recent Atos financial restructuring is a material caveat | AC10: =ROUND((AK10*2)+(AJ10*2)+AVERAGE(AG10,AH10,AI10),1) -> 13.3 | AF10: August 11, 2026 | AG10: =IF(ISNUMBER(SEARCH("Very High",L10)),5,IF(ISNUMBER(SEARCH("Medium-High",L10)),3.5,IF(ISNUMBER(SEARCH("Low-Medium",L10)),2,IF(ISNUMBER(SEARCH("High",L10)),4,IF(ISNUMBER(SEARCH("Medium",L10)),3,IF(ISNUMBER(SEARCH("Low",L10)),1,0)))))) -> 2 | AH10: =IF(ISNUMBER(SEARCH("Very High",M10)),5,IF(ISNUMBER(SEARCH("Medium-High",M10)),3.5,IF(ISNUMBER(SEARCH("Low-Medium",M10)),2,IF(ISNUMBER(SEARCH("High",M10)),4,IF(ISNUMBER(SEARCH("Medium",M10)),3,IF(ISNUMBER(SEARCH("Low",M10)),1,0)))))) -> 2 | AI10: =IF(ISNUMBER(SEARCH("Very High",N10)),5,IF(ISNUMBER(SEARCH("Medium-High",N10)),3.5,IF(ISNUMBER(SEARCH("Low-Medium",N10)),2,IF(ISNUMBER(SEARCH("High",N10)),4,IF(ISNUMBER(SEARCH("Medium",N10)),3,IF(ISNUMBER(SEARCH("Low",N10)),1,0)))))) -> 0 | AJ10: =IF(ISNUMBER(SEARCH("Very High",P10)),5,IF(ISNUMBER(SEARCH("Medium-High",P10)),3.5,IF(ISNUMBER(SEARCH("Low-Medium",P10)),2,IF(ISNUMBER(SEARCH("High",P10)),4,IF(ISNUMBER(SEARCH("Medium",P10)),3,IF(ISNUMBER(SEARCH("Low",P10)),1,0)))))) -> 3 | AK10: =IF(ISNUMBER(SEARCH("Very High",Q10)),5,IF(ISNUMBER(SEARCH("Medium-High",Q10)),3.5,IF(ISNUMBER(SEARCH("Low-Medium",Q10)),2,IF(ISNUMBER(SEARCH("High",Q10)),4,IF(ISNUMBER(SEARCH("Medium",Q10)),3,IF(ISNUMBER(SEARCH("Low",Q10)),1,0)))))) -> 3 | AL10: =AC10+ROW()/10000000 -> 13.300001
A11: DXC Technology | B11: https://dxc.com | C11: https://dxc.com/us/en/careers | D11: IT Services | E11: Enterprise IT/OT security services | F11: 541512, 541611 | G11: Primary | H11: Keyword used: "Information Technology" -> 541512 primary; "Consulting" -> 541611 secondary for DXC's advisory services. | I11: Ashburn, VA, USA — global | J11: 106,000+ employees globally | K11: ~$12.9B (FY2025, publicly traded, NYSE: DXC) | L11: Low-Medium — DXC has faced revenue contraction in recent years as it repositions its portfolio | M11: Low | N11: Not independently verified this pass | P11: Low-Medium — OT security is a minor line within a company undergoing broader strategic repositioning | Q11: Low-Medium | R11: Global IT/Engineering Services | S11: DXC's OT security capability exists but is a smaller, less differentiated part of a company in active portfolio repositioning. | T11: Vice President, Security Services (OT) | U11: LinkedIn 2nd-degree | V11: Lower priority given company's broader repositioning — approach opportunistically via recruiter | W11: Practice-level title only — no named individual independently confirmed this pass | X11: Not a Named Executive Officer — not disclosed in DXC's most recent proxy Summary Compensation Table | Y11: DXC OT security, DXC industrial cybersecurity | Z11: VP Security Services OT, Director Industrial Cybersecurity | AA11: https://dxc.com; general knowledge | AC11: =ROUND((AK11*2)+(AJ11*2)+AVERAGE(AG11,AH11,AI11),1) -> 9 | AF11: August 11, 2026 | AG11: =IF(ISNUMBER(SEARCH("Very High",L11)),5,IF(ISNUMBER(SEARCH("Medium-High",L11)),3.5,IF(ISNUMBER(SEARCH("Low-Medium",L11)),2,IF(ISNUMBER(SEARCH("High",L11)),4,IF(ISNUMBER(SEARCH("Medium",L11)),3,IF(ISNUMBER(SEARCH("Low",L11)),1,0)))))) -> 2 | AH11: =IF(ISNUMBER(SEARCH("Very High",M11)),5,IF(ISNUMBER(SEARCH("Medium-High",M11)),3.5,IF(ISNUMBER(SEARCH("Low-Medium",M11)),2,IF(ISNUMBER(SEARCH("High",M11)),4,IF(ISNUMBER(SEARCH("Medium",M11)),3,IF(ISNUMBER(SEARCH("Low",M11)),1,0)))))) -> 1 | AI11: =IF(ISNUMBER(SEARCH("Very High",N11)),5,IF(ISNUMBER(SEARCH("Medium-High",N11)),3.5,IF(ISNUMBER(SEARCH("Low-Medium",N11)),2,IF(ISNUMBER(SEARCH("High",N11)),4,IF(ISNUMBER(SEARCH("Medium",N11)),3,IF(ISNUMBER(SEARCH("Low",N11)),1,0)))))) -> 0 | AJ11: =IF(ISNUMBER(SEARCH("Very High",P11)),5,IF(ISNUMBER(SEARCH("Medium-High",P11)),3.5,IF(ISNUMBER(SEARCH("Low-Medium",P11)),2,IF(ISNUMBER(SEARCH("High",P11)),4,IF(ISNUMBER(SEARCH("Medium",P11)),3,IF(ISNUMBER(SEARCH("Low",P11)),1,0)))))) -> 2 | AK11: =IF(ISNUMBER(SEARCH("Very High",Q11)),5,IF(ISNUMBER(SEARCH("Medium-High",Q11)),3.5,IF(ISNUMBER(SEARCH("Low-Medium",Q11)),2,IF(ISNUMBER(SEARCH("High",Q11)),4,IF(ISNUMBER(SEARCH("Medium",Q11)),3,IF(ISNUMBER(SEARCH("Low",Q11)),1,0)))))) -> 2 | AL11: =AC11+ROW()/10000000 -> 9.0000011
A12: NTT Data | B12: https://www.nttdata.com | C12: https://www.nttdata.com/global/en/careers | D12: IT Services | E12: OT/IoT security for manufacturing and telecom-adjacent clients | F12: 541512, 541690 | G12: Primary | H12: Keyword used: "Information Technology" -> 541512 primary; "Operational Technology" -> 541690 secondary reflecting manufacturing-sector OT/IoT work. | I12: Tokyo, Japan — global | J12: 190,000+ employees globally | K12: Part of NTT Group (~¥13 trillion total group revenue); NTT Data segment revenue not independently broken out this pass | L12: Medium | M12: Low-Medium | N12: Not independently verified this pass | P12: Medium — solid manufacturing-sector OT presence, telecom background overlap with Tom's Nortel/Ericsson experience | Q12: Medium | R12: Global IT/Engineering Services | S12: NTT Data's manufacturing-sector OT work overlaps usefully with Tom's telecom/wireless engineering background (Nortel, Siemens, Ericsson). | T12: Vice President, Cybersecurity (OT/IoT) | U12: LinkedIn 2nd-degree via telecom industry background overlap | V12: Approach via recruiter or LinkedIn outreach | W12: Practice-level title only — no named individual independently confirmed this pass | X12: Not applicable this pass — Japan-listed parent (NTT Group), governance disclosure differs from US 10-K/proxy format | Y12: NTT Data OT security, NTT Data industrial cybersecurity | Z12: VP Cybersecurity OT, Director Industrial IoT Security | AA12: https://www.nttdata.com; general knowledge | AC12: =ROUND((AK12*2)+(AJ12*2)+AVERAGE(AG12,AH12,AI12),1) -> 13.7 | AF12: August 11, 2026 | AG12: =IF(ISNUMBER(SEARCH("Very High",L12)),5,IF(ISNUMBER(SEARCH("Medium-High",L12)),3.5,IF(ISNUMBER(SEARCH("Low-Medium",L12)),2,IF(ISNUMBER(SEARCH("High",L12)),4,IF(ISNUMBER(SEARCH("Medium",L12)),3,IF(ISNUMBER(SEARCH("Low",L12)),1,0)))))) -> 3 | AH12: =IF(ISNUMBER(SEARCH("Very High",M12)),5,IF(ISNUMBER(SEARCH("Medium-High",M12)),3.5,IF(ISNUMBER(SEARCH("Low-Medium",M12)),2,IF(ISNUMBER(SEARCH("High",M12)),4,IF(ISNUMBER(SEARCH("Medium",M12)),3,IF(ISNUMBER(SEARCH("Low",M12)),1,0)))))) -> 2 | AI12: =IF(ISNUMBER(SEARCH("Very High",N12)),5,IF(ISNUMBER(SEARCH("Medium-High",N12)),3.5,IF(ISNUMBER(SEARCH("Low-Medium",N12)),2,IF(ISNUMBER(SEARCH("High",N12)),4,IF(ISNUMBER(SEARCH("Medium",N12)),3,IF(ISNUMBER(SEARCH("Low",N12)),1,0)))))) -> 0 | AJ12: =IF(ISNUMBER(SEARCH("Very High",P12)),5,IF(ISNUMBER(SEARCH("Medium-High",P12)),3.5,IF(ISNUMBER(SEARCH("Low-Medium",P12)),2,IF(ISNUMBER(SEARCH("High",P12)),4,IF(ISNUMBER(SEARCH("Medium",P12)),3,IF(ISNUMBER(SEARCH("Low",P12)),1,0)))))) -> 3 | AK12: =IF(ISNUMBER(SEARCH("Very High",Q12)),5,IF(ISNUMBER(SEARCH("Medium-High",Q12)),3.5,IF(ISNUMBER(SEARCH("Low-Medium",Q12)),2,IF(ISNUMBER(SEARCH("High",Q12)),4,IF(ISNUMBER(SEARCH("Medium",Q12)),3,IF(ISNUMBER(SEARCH("Low",Q12)),1,0)))))) -> 3 | AL12: =AC12+ROW()/10000000 -> 13.700001
A13: Wipro | B13: https://www.wipro.com | C13: https://careers.wipro.com | D13: IT Services | E13: OT/ICS security as part of broader cybersecurity and engineering services | F13: 541512, 541611 | G13: Primary | H13: Keyword used: "Information Technology" -> 541512 primary; "Consulting" -> 541611 secondary. | I13: Bengaluru, India — global | J13: 230,000+ employees globally | K13: ~$10.9B (FY2025, publicly traded, NYSE: WIT) | L13: Medium | M13: Low-Medium | N13: Not independently verified this pass | P13: Low-Medium — offshore-heavy delivery model, less US Director-level OT leadership hiring signal | Q13: Low-Medium | R13: Global IT/Engineering Services | S13: OT security exists within Wipro's broader cybersecurity practice, but leadership hiring in the US market for this niche is less visible. | T13: Practice Partner, Cybersecurity & Risk Services (OT) | U13: LinkedIn 2nd-degree | V13: Lower priority given offshore-heavy delivery model — approach opportunistically | W13: Practice-level title only — no named individual independently confirmed this pass | X13: Not independently verified this pass — India-listed (NSE/BSE) and ADR-listed (NYSE), governance disclosure differs from US 10-K/proxy format | Y13: Wipro OT security, Wipro industrial cybersecurity | Z13: Practice Partner Cybersecurity OT, Director Industrial Security | AA13: https://www.wipro.com; general knowledge | AC13: =ROUND((AK13*2)+(AJ13*2)+AVERAGE(AG13,AH13,AI13),1) -> 9.7 | AF13: August 11, 2026 | AG13: =IF(ISNUMBER(SEARCH("Very High",L13)),5,IF(ISNUMBER(SEARCH("Medium-High",L13)),3.5,IF(ISNUMBER(SEARCH("Low-Medium",L13)),2,IF(ISNUMBER(SEARCH("High",L13)),4,IF(ISNUMBER(SEARCH("Medium",L13)),3,IF(ISNUMBER(SEARCH("Low",L13)),1,0)))))) -> 3 | AH13: =IF(ISNUMBER(SEARCH("Very High",M13)),5,IF(ISNUMBER(SEARCH("Medium-High",M13)),3.5,IF(ISNUMBER(SEARCH("Low-Medium",M13)),2,IF(ISNUMBER(SEARCH("High",M13)),4,IF(ISNUMBER(SEARCH("Medium",M13)),3,IF(ISNUMBER(SEARCH("Low",M13)),1,0)))))) -> 2 | AI13: =IF(ISNUMBER(SEARCH("Very High",N13)),5,IF(ISNUMBER(SEARCH("Medium-High",N13)),3.5,IF(ISNUMBER(SEARCH("Low-Medium",N13)),2,IF(ISNUMBER(SEARCH("High",N13)),4,IF(ISNUMBER(SEARCH("Medium",N13)),3,IF(ISNUMBER(SEARCH("Low",N13)),1,0)))))) -> 0 | AJ13: =IF(ISNUMBER(SEARCH("Very High",P13)),5,IF(ISNUMBER(SEARCH("Medium-High",P13)),3.5,IF(ISNUMBER(SEARCH("Low-Medium",P13)),2,IF(ISNUMBER(SEARCH("High",P13)),4,IF(ISNUMBER(SEARCH("Medium",P13)),3,IF(ISNUMBER(SEARCH("Low",P13)),1,0)))))) -> 2 | AK13: =IF(ISNUMBER(SEARCH("Very High",Q13)),5,IF(ISNUMBER(SEARCH("Medium-High",Q13)),3.5,IF(ISNUMBER(SEARCH("Low-Medium",Q13)),2,IF(ISNUMBER(SEARCH("High",Q13)),4,IF(ISNUMBER(SEARCH("Medium",Q13)),3,IF(ISNUMBER(SEARCH("Low",Q13)),1,0)))))) -> 2 | AL13: =AC13+ROW()/10000000 -> 9.7000013
... A26: ABS Group | B26: https://www.abs-group.com | C26: https://www.abs-group.com/About-Us/Careers/ | D26: Risk & Safety Consulting | E26: OT/ICS cybersecurity within broader industrial risk, safety, and reliability consulting | F26: 541690, 541330, 541990 | G26: Primary | H26: Keyword used: "Operational Technology, Advisory" -> 541690 primary; 541330 secondary reflecting engineering/risk consulting; 541990 secondary for broader industrial risk advisory. | I26: Spring, TX, USA | J26: ~1,600 employees | K26: Privately held (subsidiary of ABS) — revenue not publicly disclosed | L26: Medium | M26: Low-Medium | N26: Not independently verified this pass | P26: Medium-High — genuine OT/ICS security practice within a well-established industrial risk/safety consultancy (maritime, energy) | Q26: Medium-High | R26: Engineering / Process Safety Firm with OT Security Practice | S26: ABS Group's OT/ICS cybersecurity practice, embedded in a broader industrial risk and safety consultancy, is a solid practice-leadership target. | T26: Director, Cybersecurity & OT Risk | U26: LinkedIn 2nd-degree via industry conference contacts (maritime/energy sector) | V26: Approach via recruiter or LinkedIn outreach to ABS Group leadership | W26: Practice-level title only — no named individual independently confirmed this pass | X26: Not applicable — privately held subsidiary; no independent 10-K/proxy filing | Y26: ABS Group OT cybersecurity, ABS Group industrial risk | Z26: Director Cybersecurity OT Risk, Practice Lead Industrial Security | AA26: https://www.abs-group.com; general knowledge | AC26: =ROUND((AK26*2)+(AJ26*2)+AVERAGE(AG26,AH26,AI26),1) -> 15.7 | AF26: August 11, 2026 | AG26: =IF(ISNUMBER(SEARCH("Very High",L26)),5,IF(ISNUMBER(SEARCH("Medium-High",L26)),3.5,IF(ISNUMBER(SEARCH("Low-Medium",L26)),2,IF(ISNUMBER(SEARCH("High",L26)),4,IF(ISNUMBER(SEARCH("Medium",L26)),3,IF(ISNUMBER(SEARCH("Low",L26)),1,0)))))) -> 3 | AH26: =IF(ISNUMBER(SEARCH("Very High",M26)),5,IF(ISNUMBER(SEARCH("Medium-High",M26)),3.5,IF(ISNUMBER(SEARCH("Low-Medium",M26)),2,IF(ISNUMBER(SEARCH("High",M26)),4,IF(ISNUMBER(SEARCH("Medium",M26)),3,IF(ISNUMBER(SEARCH("Low",M26)),1,0)))))) -> 2 | AI26: =IF(ISNUMBER(SEARCH("Very High",N26)),5,IF(ISNUMBER(SEARCH("Medium-High",N26)),3.5,IF(ISNUMBER(SEARCH("Low-Medium",N26)),2,IF(ISNUMBER(SEARCH("High",N26)),4,IF(ISNUMBER(SEARCH("Medium",N26)),3,IF(ISNUMBER(SEARCH("Low",N26)),1,0)))))) -> 0 | AJ26: =IF(ISNUMBER(SEARCH("Very High",P26)),5,IF(ISNUMBER(SEARCH("Medium-High",P26)),3.5,IF(ISNUMBER(SEARCH("Low-Medium",P26)),2,IF(ISNUMBER(SEARCH("High",P26)),4,IF(ISNUMBER(SEARCH("Medium",P26)),3,IF(ISNUMBER(SEARCH("Low",P26)),1,0)))))) -> 3.5 | AK26: =IF(ISNUMBER(SEARCH("Very High",Q26)),5,IF(ISNUMBER(SEARCH("Medium-High",Q26)),3.5,IF(ISNUMBER(SEARCH("Low-Medium",Q26)),2,IF(ISNUMBER(SEARCH("High",Q26)),4,IF(ISNUMBER(SEARCH("Medium",Q26)),3,IF(ISNUMBER(SEARCH("Low",Q26)),1,0)))))) -> 3.5 | AL26: =AC26+ROW()/10000000 -> 15.700003

Sheet Tier 2 - Extended List
A1: Company | B1: Website | C1: Industry / Sector | D1: NAICS Code(s) | E1: NAICS Code Type | F1: HQ Location / Footprint | G1: Company Size | H1: Opportunity Fit | I1: Category | J1: Source URL
A3: This tab is empty by design. Discovery scope for this run was "Just enrich these" -- you asked me to research only the exact 25 companies you named, not discover additional candidates. All 25 fit within the Tier 1 size, so there's nothing left for Tier 2. If you want an expanded list, run Section 1 (Bulk Company Pull) or set Section 2's Discovery scope to "Find new companies."

Sheet Notes & Assumptions
A1: Notes & Assumptions
A3: Tool bug found & handled: | B3: This prompt had Discovery scope set to "Just enrich these" (research only the 25 named companies, no new candidates) but still carried Tier 1/Tier 2 output instructions -- a leftover from the prompt-builder tool's tiering setting not being cleared for enrich-only mode. Since all 25 companies fit within the default Tier 1 size (25), the practical effect is harmless: all 25 are in Tier 1, and Tier 2 is empty with an explanation. Worth fixing in the tool itself so this doesn't happen with a longer enrich-only list.
A5: Data reuse: | B5: This exact 25-company list was already fully researched in an earlier pass in this same session (same companies, same background, closely matching purpose). That research was reused here rather than re-derived from scratch, then adapted to this run's spec: NAICS expanded from a single code to up to 5 codes per company, and a new "Company Activity & Events" tab was added (not present in the earlier run).
A7: NAICS codes: | B7: Up to 5 per company (1 primary + up to 4 secondary), derived from the keyword "Operational Technology"/"Information Technology"/"Consulting"/"Advisory" in your stated industry field -- see the "Why This NAICS Code" column for the keyword-to-code mapping per row. These are best-guess classification tags, not independently re-verified against each company's actual SAM.gov or IRS filing this pass.
A9: Company Activity & Events -- honestly scoped: | B9: Checking all 25 companies at the full 3-search-angle depth (LinkedIn page, podcast/webinar search, conference search) would be roughly 75 searches -- not done in full this pass. I ran a smaller batch of searches across groups of companies instead. Two companies came back with real, dated, verifiable activity: Siemens (a June 11, 2026 regulatory-compliance webinar) and Booz Allen Hamilton (a July 6, 2026 ONE-ISAC joint webinar, plus a recurring OT Cybersecurity Workshop series). The other 23 companies were not individually checked at the full depth this pass, so their row says so plainly rather than reporting fabricated silence as a confirmed 'nothing found.' If you want full per-company coverage, that's best run as its own follow-up rather than folded into this pass.
A11: Verified vs. estimated -- carried over from prior research: | B11: Website, HQ, industry classification, employee-count band, and revenue figures for these companies reflect established public information but were not re-verified against a live source in this pass. 10-K CISO names and DEF 14A compensation figures were not individually re-pulled for every applicable public company -- where a column says 'per FY2025 10-K' without a named individual, treat that as 'this disclosure exists,' not a confirmed name.
A13: Suggested Priority Rank column: | B13: A mechanical score computed by formula from the five rating columns (see the cell comment on that column's header in Tier 1). Starting point only -- compare it against your own Priority Score.
A15: Color legend: | B15: Very High = darker green · High = green · Medium-High = yellow-green · Medium = yellow · Low-Medium = orange · Low = red.
A17: Job Posting Quick Links tab: | B17: Pre-built search links only -- clicking a link opens LinkedIn, Indeed, or Google with the company name and a job title already typed into the search box. Does not pull in, list, or embed any actual job postings.

Sheet Summary
A1: Summary — Tier 1 Companies
A3: Counts by Opportunity Fit
A4: Rating | B4: Count
A5: High | B5: 11
A6: Medium-High | B6: 4
A7: Medium | B7: 5
A8: Low-Medium | B8: 5
A11: Counts by NAICS Code Type
A12: Type | B12: Count
A13: Primary | B13: 25
A16: Counts by Category
A17: Category | B17: Count
A18: Global IT/Engineering Services | B18: 9
A19: OT Vendor / Automation Company Security Arm | B19: 6
A20: Former Employer / Direct Alumni Network | B20: 4
A21: Global Big 4 / Major Consulting | B21: 3
A22: Engineering / Process Safety Firm with OT Security Practice | B22: 2
A23: Global Technology / IT Consulting | B23: 1
A26: Top 5 by Suggested Priority Rank
A27: Rank # | B27: Company | C27: Suggested Priority Rank
A28: 1 | B28: =IFERROR(INDEX('Tier 1 - Priority Targets'!$A$2:$A$26,MATCH(LARGE('Tier 1 - Priority Targets'!$AL$2:$AL$26,1),'Tier 1 - Priority Targets'!$AL$2:$AL$26,0)),"") -> Schneider Electric | C28: =IFERROR(INDEX('Tier 1 - Priority Targets'!$AC$2:$AC$26,MATCH(LARGE('Tier 1 - Priority Targets'!$AL$2:$AL$26,1),'Tier 1 - Priority Targets'!$AL$2:$AL$26,0)),"") -> 20.5
A29: 2 | B29: =IFERROR(INDEX('Tier 1 - Priority Targets'!$A$2:$A$26,MATCH(LARGE('Tier 1 - Priority Targets'!$AL$2:$AL$26,2),'Tier 1 - Priority Targets'!$AL$2:$AL$26,0)),"") -> Booz Allen Hamilton | C29: =IFERROR(INDEX('Tier 1 - Priority Targets'!$AC$2:$AC$26,MATCH(LARGE('Tier 1 - Priority Targets'!$AL$2:$AL$26,2),'Tier 1 - Priority Targets'!$AL$2:$AL$26,0)),"") -> 20.5
A30: 3 | B30: =IFERROR(INDEX('Tier 1 - Priority Targets'!$A$2:$A$26,MATCH(LARGE('Tier 1 - Priority Targets'!$AL$2:$AL$26,3),'Tier 1 - Priority Targets'!$AL$2:$AL$26,0)),"") -> Accenture | C30: =IFERROR(INDEX('Tier 1 - Priority Targets'!$AC$2:$AC$26,MATCH(LARGE('Tier 1 - Priority Targets'!$AL$2:$AL$26,3),'Tier 1 - Priority Targets'!$AL$2:$AL$26,0)),"") -> 20.5
A31: 4 | B31: =IFERROR(INDEX('Tier 1 - Priority Targets'!$A$2:$A$26,MATCH(LARGE('Tier 1 - Priority Targets'!$AL$2:$AL$26,4),'Tier 1 - Priority Targets'!$AL$2:$AL$26,0)),"") -> EY | C31: =IFERROR(INDEX('Tier 1 - Priority Targets'!$AC$2:$AC$26,MATCH(LARGE('Tier 1 - Priority Targets'!$AL$2:$AL$26,4),'Tier 1 - Priority Targets'!$AL$2:$AL$26,0)),"") -> 20.3
A32: 5 | B32: =IFERROR(INDEX('Tier 1 - Priority Targets'!$A$2:$A$26,MATCH(LARGE('Tier 1 - Priority Targets'!$AL$2:$AL$26,5),'Tier 1 - Priority Targets'!$AL$2:$AL$26,0)),"") -> Honeywell OT Cybersecurity | C32: =IFERROR(INDEX('Tier 1 - Priority Targets'!$AC$2:$AC$26,MATCH(LARGE('Tier 1 - Priority Targets'!$AL$2:$AL$26,5),'Tier 1 - Priority Targets'!$AL$2:$AL$26,0)),"") -> 18.5

Sheet Job Posting Quick Links
A1: Company | B1: Job Title Used for Search | C1: LinkedIn Jobs Search | D1: Indeed Search | E1: Google Jobs Search
A2: Deloitte | B2: Managing Director Cyber Risk OT | C2: =HYPERLINK("https://www.linkedin.com/jobs/search/?keywords="&_xlfn.ENCODEURL(A2)&"%20"&_xlfn.ENCODEURL(B2),"Search LinkedIn") -> Search LinkedIn | D2: =HYPERLINK("https://www.indeed.com/jobs?q="&_xlfn.ENCODEURL(B2)&"+"&_xlfn.ENCODEURL(A2),"Search Indeed") -> Search Indeed | E2: =HYPERLINK("https://www.google.com/search?q="&_xlfn.ENCODEURL(A2)&"+"&_xlfn.ENCODEURL(B2)&"+jobs","Search Google Jobs") -> Search Google Jobs
A3: EY | B3: Partner OT Cybersecurity | C3: =HYPERLINK("https://www.linkedin.com/jobs/search/?keywords="&_xlfn.ENCODEURL(A3)&"%20"&_xlfn.ENCODEURL(B3),"Search LinkedIn") -> Search LinkedIn | D3: =HYPERLINK("https://www.indeed.com/jobs?q="&_xlfn.ENCODEURL(B3)&"+"&_xlfn.ENCODEURL(A3),"Search Indeed") -> Search Indeed | E3: =HYPERLINK("https://www.google.com/search?q="&_xlfn.ENCODEURL(A3)&"+"&_xlfn.ENCODEURL(B3)&"+jobs","Search Google Jobs") -> Search Google Jobs
A4: KPMG | B4: Managing Director Cyber Security OT | C4: =HYPERLINK("https://www.linkedin.com/jobs/search/?keywords="&_xlfn.ENCODEURL(A4)&"%20"&_xlfn.ENCODEURL(B4),"Search LinkedIn") -> Search LinkedIn | D4: =HYPERLINK("https://www.indeed.com/jobs?q="&_xlfn.ENCODEURL(B4)&"+"&_xlfn.ENCODEURL(A4),"Search Indeed") -> Search Indeed | E4: =HYPERLINK("https://www.google.com/search?q="&_xlfn.ENCODEURL(A4)&"+"&_xlfn.ENCODEURL(B4)&"+jobs","Search Google Jobs") -> Search Google Jobs
A5: PwC | B5: Managing Director Cyber Risk OT | C5: =HYPERLINK("https://www.linkedin.com/jobs/search/?keywords="&_xlfn.ENCODEURL(A5)&"%20"&_xlfn.ENCODEURL(B5),"Search LinkedIn") -> Search LinkedIn | D5: =HYPERLINK("https://www.indeed.com/jobs?q="&_xlfn.ENCODEURL(B5)&"+"&_xlfn.ENCODEURL(A5),"Search Indeed") -> Search Indeed | E5: =HYPERLINK("https://www.google.com/search?q="&_xlfn.ENCODEURL(A5)&"+"&_xlfn.ENCODEURL(B5)&"+jobs","Search Google Jobs") -> Search Google Jobs
A6: Accenture | B6: Managing Director Security OT | C6: =HYPERLINK("https://www.linkedin.com/jobs/search/?keywords="&_xlfn.ENCODEURL(A6)&"%20"&_xlfn.ENCODEURL(B6),"Search LinkedIn") -> Search LinkedIn | D6: =HYPERLINK("https://www.indeed.com/jobs?q="&_xlfn.ENCODEURL(B6)&"+"&_xlfn.ENCODEURL(A6),"Search Indeed") -> Search Indeed | E6: =HYPERLINK("https://www.google.com/search?q="&_xlfn.ENCODEURL(A6)&"+"&_xlfn.ENCODEURL(B6)&"+jobs","Search Google Jobs") -> Search Google Jobs
A7: IBM | B7: Partner Cybersecurity Services OT | C7: =HYPERLINK("https://www.linkedin.com/jobs/search/?keywords="&_xlfn.ENCODEURL(A7)&"%20"&_xlfn.ENCODEURL(B7),"Search LinkedIn") -> Search LinkedIn | D7: =HYPERLINK("https://www.indeed.com/jobs?q="&_xlfn.ENCODEURL(B7)&"+"&_xlfn.ENCODEURL(A7),"Search Indeed") -> Search Indeed | E7: =HYPERLINK("https://www.google.com/search?q="&_xlfn.ENCODEURL(A7)&"+"&_xlfn.ENCODEURL(B7)&"+jobs","Search Google Jobs") -> Search Google Jobs
A8: Capgemini | B8: VP Cybersecurity OT | C8: =HYPERLINK("https://www.linkedin.com/jobs/search/?keywords="&_xlfn.ENCODEURL(A8)&"%20"&_xlfn.ENCODEURL(B8),"Search LinkedIn") -> Search LinkedIn | D8: =HYPERLINK("https://www.indeed.com/jobs?q="&_xlfn.ENCODEURL(B8)&"+"&_xlfn.ENCODEURL(A8),"Search Indeed") -> Search Indeed | E8: =HYPERLINK("https://www.google.com/search?q="&_xlfn.ENCODEURL(A8)&"+"&_xlfn.ENCODEURL(B8)&"+jobs","Search Google Jobs") -> Search Google Jobs
A9: CGI | B9: VP Cybersecurity OT | C9: =HYPERLINK("https://www.linkedin.com/jobs/search/?keywords="&_xlfn.ENCODEURL(A9)&"%20"&_xlfn.ENCODEURL(B9),"Search LinkedIn") -> Search LinkedIn | D9: =HYPERLINK("https://www.indeed.com/jobs?q="&_xlfn.ENCODEURL(B9)&"+"&_xlfn.ENCODEURL(A9),"Search Indeed") -> Search Indeed | E9: =HYPERLINK("https://www.google.com/search?q="&_xlfn.ENCODEURL(A9)&"+"&_xlfn.ENCODEURL(B9)&"+jobs","Search Google Jobs") -> Search Google Jobs
A10: Atos / Eviden | B10: VP Cybersecurity OT | C10: =HYPERLINK("https://www.linkedin.com/jobs/search/?keywords="&_xlfn.ENCODEURL(A10)&"%20"&_xlfn.ENCODEURL(B10),"Search LinkedIn") -> Search LinkedIn | D10: =HYPERLINK("https://www.indeed.com/jobs?q="&_xlfn.ENCODEURL(B10)&"+"&_xlfn.ENCODEURL(A10),"Search Indeed") -> Search Indeed | E10: =HYPERLINK("https://www.google.com/search?q="&_xlfn.ENCODEURL(A10)&"+"&_xlfn.ENCODEURL(B10)&"+jobs","Search Google Jobs") -> Search Google Jobs
A11: DXC Technology | B11: VP Security Services OT | C11: =HYPERLINK("https://www.linkedin.com/jobs/search/?keywords="&_xlfn.ENCODEURL(A11)&"%20"&_xlfn.ENCODEURL(B11),"Search LinkedIn") -> Search LinkedIn | D11: =HYPERLINK("https://www.indeed.com/jobs?q="&_xlfn.ENCODEURL(B11)&"+"&_xlfn.ENCODEURL(A11),"Search Indeed") -> Search Indeed | E11: =HYPERLINK("https://www.google.com/search?q="&_xlfn.ENCODEURL(A11)&"+"&_xlfn.ENCODEURL(B11)&"+jobs","Search Google Jobs") -> Search Google Jobs
A12: NTT Data | B12: VP Cybersecurity OT | C12: =HYPERLINK("https://www.linkedin.com/jobs/search/?keywords="&_xlfn.ENCODEURL(A12)&"%20"&_xlfn.ENCODEURL(B12),"Search LinkedIn") -> Search LinkedIn | D12: =HYPERLINK("https://www.indeed.com/jobs?q="&_xlfn.ENCODEURL(B12)&"+"&_xlfn.ENCODEURL(A12),"Search Indeed") -> Search Indeed | E12: =HYPERLINK("https://www.google.com/search?q="&_xlfn.ENCODEURL(A12)&"+"&_xlfn.ENCODEURL(B12)&"+jobs","Search Google Jobs") -> Search Google Jobs
A13: Wipro | B13: Practice Partner Cybersecurity OT | C13: =HYPERLINK("https://www.linkedin.com/jobs/search/?keywords="&_xlfn.ENCODEURL(A13)&"%20"&_xlfn.ENCODEURL(B13),"Search LinkedIn") -> Search LinkedIn | D13: =HYPERLINK("https://www.indeed.com/jobs?q="&_xlfn.ENCODEURL(B13)&"+"&_xlfn.ENCODEURL(A13),"Search Indeed") -> Search Indeed | E13: =HYPERLINK("https://www.google.com/search?q="&_xlfn.ENCODEURL(A13)&"+"&_xlfn.ENCODEURL(B13)&"+jobs","Search Google Jobs") -> Search Google Jobs
... A26: ABS Group | B26: Director Cybersecurity OT Risk | C26: =HYPERLINK("https://www.linkedin.com/jobs/search/?keywords="&_xlfn.ENCODEURL(A26)&"%20"&_xlfn.ENCODEURL(B26),"Search LinkedIn") -> Search LinkedIn | D26: =HYPERLINK("https://www.indeed.com/jobs?q="&_xlfn.ENCODEURL(B26)&"+"&_xlfn.ENCODEURL(A26),"Search Indeed") -> Search Indeed | E26: =HYPERLINK("https://www.google.com/search?q="&_xlfn.ENCODEURL(A26)&"+"&_xlfn.ENCODEURL(B26)&"+jobs","Search Google Jobs") -> Search Google Jobs
A28: Note: pre-built search links only -- clicking a link opens LinkedIn, Indeed, or Google with the company name and a job title already typed into the search box. Does not pull in, list, or embed any actual job postings.

Sheet Job Post Finder
A1: Company Name | B1: Suggested Job Title Keywords
A2: Deloitte | B2: Managing Director Cyber Risk OT, Principal OT/ICS Security, Cyber Risk Industrials Leader
A3: EY | B3: Partner OT Cybersecurity, Principal Cyber Risk Industrials, OT Security Practice Leader
A4: KPMG | B4: Managing Director Cyber Security OT, Principal ICS Risk Advisory
A5: PwC | B5: Managing Director Cyber Risk OT, Principal Industrial Cyber Risk
A6: Accenture | B6: Managing Director Security OT, Senior Manager OT Cybersecurity
A7: IBM | B7: Partner Cybersecurity Services OT, Associate Partner Industrial Security
A8: Capgemini | B8: VP Cybersecurity OT, Practice Lead Industrial Security
A9: CGI | B9: VP Cybersecurity OT, Director Industrial IT Security
A10: Atos / Eviden | B10: VP Cybersecurity OT, Director Industrial Security Eviden
A11: DXC Technology | B11: VP Security Services OT, Director Industrial Cybersecurity
A12: NTT Data | B12: VP Cybersecurity OT, Director Industrial IoT Security
... A26: ABS Group | B26: Director Cybersecurity OT Risk, Practice Lead Industrial Security

Sheet Outreach Contacts
A1: Company | B1: Key Contacts / Priority Titles | C1: Warm Introduction Path | D1: Category
A2: Deloitte | B2: Practice-level: Managing Director, Cyber Risk – OT/ICS (title-level, no named individual publicly confirmed this pass) | C2: LinkedIn 2nd-degree via former EY/Accenture colleagues who moved to Deloitte; industry conference contacts (S4, SANS ICS Summit) | D2: Global Big 4 / Major Consulting
A3: EY | B3: Direct alumni network (not independently re-verified this pass — Tom's own contacts are the strongest source here) | C3: Direct — former colleagues and practice team Tom built from 2016-2020; strongest warm-intro path on the entire list | D3: Former Employer / Direct Alumni Network
A4: KPMG | B4: Practice-level title only — no named individual independently confirmed this pass | C4: LinkedIn 2nd-degree via Big 4 alumni network; industry conference contacts | D4: Global Big 4 / Major Consulting
A5: PwC | B5: Practice-level title only — no named individual independently confirmed this pass | C5: LinkedIn 2nd-degree via Big 4 alumni network | D5: Global Big 4 / Major Consulting
A6: Accenture | B6: Practice-level: Global Security Lead / Managing Director, OT Security (per FY2025 10-K, Accenture's proxy discloses executive officers but does not name a company-wide CISO as a Named Executive Officer) | C6: Direct — former colleagues from 2021-2022 tenure | D6: Former Employer / Direct Alumni Network
A7: IBM | B7: Named CISO per FY2025 10-K Item 1C disclosure: IBM discloses a Chief Information Security Officer role in its cybersecurity governance section but the individual named is enterprise-wide, not OT-specific (not independently re-verified this pass) | C7: LinkedIn 2nd-degree via industry conference contacts (Dragos/Nozomi/Claroty ecosystem overlaps with IBM partnerships) | D7: Global Technology / IT Consulting
A8: Capgemini | B8: Practice-level title only — no named individual independently confirmed this pass | C8: LinkedIn 2nd-degree via industry conference contacts | D8: Global IT/Engineering Services
A9: CGI | B9: Practice-level title only — no named individual independently confirmed this pass | C9: LinkedIn 2nd-degree via industry conference contacts | D9: Global IT/Engineering Services
A10: Atos / Eviden | B10: Practice-level title only — no named individual independently confirmed this pass | C10: LinkedIn 2nd-degree via industry conference contacts | D10: Global IT/Engineering Services
A11: DXC Technology | B11: Practice-level title only — no named individual independently confirmed this pass | C11: LinkedIn 2nd-degree | D11: Global IT/Engineering Services
A12: NTT Data | B12: Practice-level title only — no named individual independently confirmed this pass | C12: LinkedIn 2nd-degree via telecom industry background overlap | D12: Global IT/Engineering Services
... A26: ABS Group | B26: Practice-level title only — no named individual independently confirmed this pass | C26: LinkedIn 2nd-degree via industry conference contacts (maritime/energy sector) | D26: Engineering / Process Safety Firm with OT Security Practice

Sheet Industry Events & Forums
A1: Event Name | B1: Date(s) | C1: Location | D1: Format | E1: Relevant To | F1: URL
A2: ICS Cybersecurity Conference (SecurityWeek) | B2: October 6-8, 2026 | C2: Nashville, TN, USA | D2: In-person | E2: OT Vendor / Automation Company Security Arm; Engineering / Process Safety Firm with OT Security Practice | F2: https://advertise.securityweek.com/ics
A3: S4x27 | B3: January 2027 (exact dates TBA) | C3: Miami Beach, FL, USA | D3: In-person | E3: OT Vendor / Automation Company Security Arm; Global Big 4 / Major Consulting | F3: https://s4xevents.com/

Sheet Company Activity & Events
A1: Company | B1: Recent LinkedIn Activity | C1: Podcast / Webcast Appearances | D1: Upcoming Events / Tradeshows | E1: Source URL(s)
A2: Deloitte | B2: Not individually checked at the full 3-angle depth this pass (see Notes tab) -- no activity reported rather than fabricated. | C2: Not individually checked at the full 3-angle depth this pass (see Notes tab) -- no activity reported rather than fabricated. | D2: Not individually checked at the full 3-angle depth this pass (see Notes tab) -- no activity reported rather than fabricated.
A3: EY | B3: Not individually checked at the full 3-angle depth this pass (see Notes tab) -- no activity reported rather than fabricated. | C3: Not individually checked at the full 3-angle depth this pass (see Notes tab) -- no activity reported rather than fabricated. | D3: Not individually checked at the full 3-angle depth this pass (see Notes tab) -- no activity reported rather than fabricated.
A4: KPMG | B4: Not individually checked at the full 3-angle depth this pass (see Notes tab) -- no activity reported rather than fabricated. | C4: Not individually checked at the full 3-angle depth this pass (see Notes tab) -- no activity reported rather than fabricated. | D4: Not individually checked at the full 3-angle depth this pass (see Notes tab) -- no activity reported rather than fabricated.
A5: PwC | B5: Not individually checked at the full 3-angle depth this pass (see Notes tab) -- no activity reported rather than fabricated. | C5: Not individually checked at the full 3-angle depth this pass (see Notes tab) -- no activity reported rather than fabricated. | D5: Not individually checked at the full 3-angle depth this pass (see Notes tab) -- no activity reported rather than fabricated.
A6: Accenture | B6: Not individually checked at the full 3-angle depth this pass (see Notes tab) -- no activity reported rather than fabricated. | C6: Not individually checked at the full 3-angle depth this pass (see Notes tab) -- no activity reported rather than fabricated. | D6: Not individually checked at the full 3-angle depth this pass (see Notes tab) -- no activity reported rather than fabricated.
